<?xml version="1.0" encoding="utf-8"?>
<!-- This URDF was automatically created by SolidWorks to URDF Exporter! Originally created by Stephen Brawner (brawner@gmail.com) 
     Commit Version: 1.6.0-4-g7f85cfe  Build Version: 1.6.7995.38578
     For more information, please see http://wiki.ros.org/sw_urdf_exporter -->
<robot
  name="Inverted">
  <link
    name="base_link">
    <inertial>
      <origin
        xyz="9.41147719171446E-20 -0.005 -1.27612101537895E-17"
        rpy="0 0 0" />
      <mass
        value="0.36" />
      <inertia
        ixx="0.000435"
        ixy="5.48063399380373E-39"
        ixz="-7.97183126371452E-38"
        iyy="0.003132"
        iyz="-1.37015849845093E-37"
        izz="0.002703" />
    </inertial>
    <visual>
      <origin
        xyz="0 0 0"
        rpy="0 0 0" />
      <geometry>
        <mesh
          filename="meshes/base_link.STL" />
      </geometry>
      <material
        name="">
        <color
          rgba="0.792156862745098 0.819607843137255 0.933333333333333 1" />
      </material>
    </visual>
    <collision>
      <origin
        xyz="0 0 0"
        rpy="0 0 0" />
      <geometry>
        <mesh
          filename="meshes/base_link.STL" />
      </geometry>
    </collision>
  </link>
  <link
    name="Link 1">
    <inertial>
      <origin
        xyz="-0.080001300538417 0.0303978287884689 0.01"
        rpy="0 0 0" />
      <mass
        value="0.969643805509808" />
      <inertia
        ixx="0.00112126184431704"
        ixy="4.9940675211926E-08"
        ixz="4.92080138273582E-20"
        iyy="0.00286598534972227"
        iyz="-5.54499201811117E-22"
        izz="0.00235204730392851" />
    </inertial>
    <visual>
      <origin
        xyz="0 0 0"
        rpy="0 0 0" />
      <geometry>
        <mesh
          filename="meshes/Link 1.STL" />
      </geometry>
      <material
        name="">
        <color
          rgba="0.792156862745098 0.819607843137255 0.933333333333333 1" />
      </material>
    </visual>
    <collision>
      <origin
        xyz="0 0 0"
        rpy="0 0 0" />
      <geometry>
        <mesh
          filename="meshes/Link 1.STL" />
      </geometry>
    </collision>
  </link>
  <joint
    name="Joint 0"
    type="prismatic">
    <origin
      xyz="0.052321 0.01 0"
      rpy="1.5708 0 0" />
    <parent
      link="base_link" />
    <child
      link="Link 1" />
    <axis
      xyz="1 0 0" />
    <limit
      lower="0"
      upper="0"
      effort="0"
      velocity="0" />
  </joint>
  <link
    name="Link 2">
    <inertial>
      <origin
        xyz="7.37800101360819E-08 0.0179967913638322 0.0147589901554167"
        rpy="0 0 0" />
      <mass
        value="0.0153450624731169" />
      <inertia
        ixx="1.49832708606931E-05"
        ixy="1.37879357943612E-11"
        ixz="-1.96778957549863E-11"
        iyy="7.09426238566816E-06"
        iyz="-1.37791984023545E-06"
        izz="8.12496286448383E-06" />
    </inertial>
    <visual>
      <origin
        xyz="0 0 0"
        rpy="0 0 0" />
      <geometry>
        <mesh
          filename="meshes/Link 2.STL" />
      </geometry>
      <material
        name="">
        <color
          rgba="0.792156862745098 0.819607843137255 0.933333333333333 1" />
      </material>
    </visual>
    <collision>
      <origin
        xyz="0 0 0"
        rpy="0 0 0" />
      <geometry>
        <mesh
          filename="meshes/Link 2.STL" />
      </geometry>
    </collision>
  </link>
  <joint
    name="Joint 2"
    type="continuous">
    <origin
      xyz="-0.08 0.07 0"
      rpy="0 0 -0.09439" />
    <parent
      link="Link 1" />
    <child
      link="Link 2" />
    <axis
      xyz="0 0 1" />
  </joint>
</robot>