<mujoco model="wx250s">
  <compiler angle="radian" texturedir="simplifiedassets" autolimits="true"/>
  <option timestep="0.005" iterations="20" integrator="Euler" />

  <custom>
    <numeric data="10000" name="constraint_limit_stiffness"/>
    <numeric data="20000" name="constraint_stiffness"/>
    <numeric data="1 1 1 1 1 1 1 1 1 1" name="constraint_ang_damping"/>
    <numeric data="0.1" name="constraint_vel_damping"/> <!-- -0.1 -->
    <numeric data="1.0" name="vel_damping"/>
    <numeric data="1.0" name="ang_damping"/>
    <numeric data="1.0" name="baumgarte_erp"/>
    <numeric data="0.3" name="spring_mass_scale"/> <!-- 0.5 -->
    <numeric data="1.0" name="spring_inertia_scale"/>
    <numeric data="50" name="solver_maxls"/>
  </custom>

  <asset>
    <texture builtin="checker" height="100" name="texplane" rgb1="0 0 0" rgb2="0.8 0.8 0.8" type="2d" width="100"/>
    <material name="MatPlane" reflectance="0.5" shininess="1" specular="1" texrepeat="60 60" texture="texplane"/>
  </asset>

  <default>
    <default class="wx250s">
      <!--<joint axis="0 1 0" frictionloss="0.1" armature="0.1"/>-->
      <joint axis="0 1 0"  armature="0.1"/>
      <position kp="50" forcerange="-5 5"/> <!-- />--> <!-- dampratio="0.95" -->
     <!-- <default class="visual">
        <geom type="mesh" contype="0" conaffinity="0" density="0" group="2" material="black"/>
      </default>-->
      <default class="collision">
        <geom group="3" type="mesh"/>
        <default class="sphere_collision">
          <geom type="sphere" size="0.0006" rgba="1 0 0 1"/>
        </default>
      </default>
      <default class="nocollision">
        <geom group="3" type="mesh" contype="0" conaffinity="0"/>
        <default class="sphere_nocollision">
          <geom type="sphere" size="0.0006" rgba="1 0 0 1"/>
        </default>
      </default>
      <default class="boxcollision">
        <geom group="3" rgba="1 0 0 1" type="box"/>
      </default>
    </default>
  </default>

  <worldbody>
    <light cutoff="100" diffuse="1 1 1" dir="-0 0 -1.3" directional="true" exponent="1" pos="0 0 1.3" specular=".1 .1 .1"/>
    <geom contype="1" conaffinity="1" condim="3" material="MatPlane" name="floor" pos="0 0 0" rgba="0.8 0.9 0.8 1" size="40 40 40" type="plane" />
    <body name="wx250s/base_link" childclass="wx250s">
      <camera name="tracking" mode="fixed" pos="0 -2 2" xyaxes="1 0 0 0 1 1"/>
      <joint type="slide" stiffness="1000" damping="1000" frictionloss="0" armature="1000"  range="-0.000001 0.000001" name="baseinertia"/>
      <inertial pos="-0.0380446 0.000613892 0.0193354" quat="0.509292 0.490887 -0.496359 0.503269" mass="2000.0"
        diaginertia="0.00252518 0.00211519 0.000690737"/>
      <!-- insanely high mass to fix robot in place -->
      <geom quat="1 0 0 1" type="box" size="0.076536 0.116768 0.0358" rgba="0 1 0 1" pos="-0.038268 0 0.0358"/>
      <!--
      <geom quat="1 0 0 1" mesh="wx250s_1_base" class="visual"/>
      <geom quat="1 0 0 1" mesh="wx250s_1_base" class="nocollision"/>-->
      <body name="wx250s/shoulder_link" pos="0 0 0.072">
        <inertial pos="2.23482e-05 4.14609e-05 0.0066287" quat="0.0130352 0.706387 0.012996 0.707586" mass="0.480879"
          diaginertia="0.000588946 0.000555655 0.000378999"/>
        <joint name="waist" axis="0 0 1" range="-3.14158 3.14158"/>
        <geom quat="1 0 0 1" type="capsule" size="0.051090337336063385 0.0000146249999180436134" rgba="0 1 0 1" pos="0 0 -0.003" />
        <!--<geom pos="0 0 -0.003" quat="1 0 0 1" mesh="wx250s_2_shoulder" class="visual"/>
        <geom pos="0 0 -0.003" quat="1 0 0 1" mesh="wx250s_2_shoulder" class="nocollision"/>-->
        <body name="wx250s/upper_arm_link" pos="0 0 0.03865">
          <inertial pos="0.0171605 2.725e-07 0.191323" quat="0.705539 0.0470667 -0.0470667 0.705539" mass="0.430811"
            diaginertia="0.00364425 0.003463 0.000399348"/>
          <joint name="shoulder" range="-1.88496 1.98968"/>
          <geom quat="1 0 0 1" type="capsule" size=" 0.00704100003093481064 0.14145001769065857" rgba="1 0 0 1" pos="0 0 0.11" contype="0" conaffinity="0"/>
          <geom quat="0 0 1 1" type="capsule" size=" 0.0274100003093481064 0.014145001769065857" rgba="1 0 0 0.2" pos="0.02 0 0.245"/>
          <!--<geom quat="1 0 0 1" mesh="wx250s_3_upper_arm" class="visual"/>
          <geom quat="1 0 0 1" mesh="wx250s_3_upper_arm" class="nocollision"/>-->
          <body name="wx250s/upper_forearm_link" pos="0.04975 0 0.25">
            <inertial pos="0.107963 0.000115876 0" quat="0.000980829 0.707106 -0.000980829 0.707106" mass="0.234589"
              diaginertia="0.000888 0.000887807 3.97035e-05"/>
            <joint name="elbow" range="-2.14675 1.6057"/>
              <geom quat="0 1 0 1" type="capsule" size="0.00704100003093481064 0.09" rgba="0 0 1 1" pos="0.09 0 0.0" contype="0" conaffinity="0"/>
            <!--<geom mesh="wx250s_4_upper_forearm" class="visual"/>
            <geom mesh="wx250s_4_upper_forearm" class="nocollision"/>-->
            <body name="wx250s/lower_forearm_link" pos="0.175 0 0">
              <inertial pos="0.0374395 0.00522252 0" quat="-0.0732511 0.703302 0.0732511 0.703302" mass="0.220991"
                diaginertia="0.0001834 0.000172527 5.88633e-05"/>
              <joint name="forearm_roll" axis="1 0 0" range="-3.14158 3.14158"/>
              <geom quat="0 1 0 1" type="capsule" size="0.0262499983906746 0.02449861913919449" rgba="1 1 0 1" pos="0.04 0 0" />
              <!--<geom quat="0 1 0 0" mesh="wx250s_5_lower_forearm" class="visual" rgba="1 0 0 0.1"/>
              <geom quat="0 1 0 0" mesh="wx250s_5_lower_forearm" class="nocollision"/>-->
              <body name="wx250s/wrist_link" pos="0.075 0 0">
                <inertial pos="0.04236 -1.0663e-05 0.010577" quat="0.608721 0.363497 -0.359175 0.606895" mass="0.084957"
                  diaginertia="3.29057e-05 3.082e-05 2.68343e-05"/>
                <joint name="wrist_angle" axis="0 1 0" range="-1.74533 2.14675"/>
                <geom quat="0 1 0 1" type="capsule" size="0.0212499983906746 0.01049861913919449" rgba="0 1 1 1" pos="0.04 0 0.015" contype="0" conaffinity="0"/>
                <!--<geom quat="1 0 0 1" mesh="wx250s_6_wrist" class="visual" rgba="1 0 0 0.1"/>
                <geom quat="1 0 0 1" mesh="wx250s_6_wrist" class="collision"/>-->
                <body name="wx250s/gripper_link" pos="0.065 0 0">
                  <inertial pos="0.0325296 4.2061e-07 0.0090959" quat="0.546081 0.419626 0.62801 0.362371"
                    mass="0.110084" diaginertia="0.00307592 0.00307326 0.0030332"/>
                  <joint name="wrist_rotate" axis="1 0 0" range="-3.14158 3.14158"/>
                  <geom quat="0 1 0 1" type="capsule" size="0.02212499983906746 0.0005049861913919449" rgba="0 1 1 1" pos="0.025 0 0.015" contype="0" conaffinity="0"/>
                  <!--<geom pos="-0.02 0 0" quat="1 0 0 1" mesh="wx250s_7_gripper" class="visual" rgba="1 0 0 0.1"/>
                  <geom pos="-0.02 0 0" quat="1 0 0 1" mesh="wx250s_7_gripper" class="collision"/>-->
                  <geom quat="0 0 1 1" type="capsule" size="0.0122499983906746 0.04049861913919449" rgba="1 0 1 1" pos="0.059 0 0" />
                  <!--<geom pos="-0.02 0 0" quat="1 0 0 1" mesh="wx250s_9_gripper_bar" class="visual" rgba="1 0 0 0.1"/>
                  <geom pos="-0.02 0 0" quat="1 0 0 1" mesh="wx250s_9_gripper_bar" class="collision"/>-->
                  <body name="wx250s/left_finger_link" pos="0.066 0 0">
                    <inertial pos="0.013816 0 0" quat="0.705384 0.705384 -0.0493271 -0.0493271" mass="0.016246"
                      diaginertia="4.79509e-06 3.7467e-06 1.48651e-06"/>
                    <joint name="left_finger" axis="0 1 0" type="slide" range="0.015 0.037"/>
                    <geom quat="0 1 0 1" type="capsule" size="0.0071522499983906746 0.01049861913919449" rgba="0.5 0 1 1" pos="0.025 -0.005 0"/>
                    <!--
                    <geom pos="0 0.005 0" quat="0 0 0 -1" mesh="wx250s_10_gripper_finger" class="visual" rgba="1 0 0 0.1"/>
                    <geom pos="0 0.005 0" quat="0 0 0 -1" mesh="wx250s_10_gripper_finger" class="collision"/>-->
                    <geom name="left/left_g0" pos="0.042 -0.009 0.012" class="sphere_collision"/>
                    <geom name="left/left_g1" pos="0.042 -0.009 -0.012" class="sphere_collision"/>
                  </body>
                  <body name="wx250s/right_finger_link" pos="0.066 0 0">
                    <inertial pos="0.013816 0 0" quat="0.705384 0.705384 0.0493271 0.0493271" mass="0.016246"
                      diaginertia="4.79509e-06 3.7467e-06 1.48651e-06"/>
                    <joint name="right_finger" axis="0 1 0" type="slide" range="-0.037 -0.015"/>
                    <geom quat="0 1 0 1" type="capsule" size="0.0071522499983906746 0.01049861913919449" rgba="0.5 0 1 1" pos="0.025 0.005 0"/>
                    <!--
                    <geom pos="0 -0.005 0" quat="0 0 1 0" mesh="wx250s_10_gripper_finger" class="visual"/>
                    <geom pos="0 -0.005 0" quat="0 0 1 0" mesh="wx250s_10_gripper_finger" class="collision"/>-->
                    <geom name="right/right_g0" pos="0.042 0.009 0.012" class="sphere_collision"/>
                    <geom name="right/right_g1" pos="0.042 0.009 -0.012" class="sphere_collision"/>
                  </body>
                </body>
              </body>
            </body>
          </body>
        </body>
      </body>
    </body>
    <body name="target" pos="0 0 0.01" gravcomp="1">
        <!-- The joint `ref` attributes are removed for brax. -->
        <joint armature="0" axis="1 0 0" damping="0" limited="true" name="target_x" pos="0 0 0" range="-.66 .66" stiffness="0" type="slide"/>
        <joint armature="0" axis="0 1 0" damping="0" limited="true" name="target_y" pos="0 0 0" range="-.66 .66" stiffness="0" type="slide"/>
        <joint armature="0" axis="0 0 1" damping="0" limited="true" name="target_z" pos="0 0 0" range="-.66 .66" stiffness="0" type="slide"/>
        <geom conaffinity="0" contype="0" name="target" pos="0 0 0" size=".009" type="sphere" rgba="0 1 0 1"/>
    </body>
  </worldbody>

  <!--
  <contact>
    <exclude body1="wx250s/base_link" body2="wx250s/shoulder_link"/>
    <exclude body1="wx250s/base_link" body2="wx250s/upper_arm_link"/>
    <exclude body1="wx250s/shoulder_link" body2="wx250s/upper_arm_link"/>
  </contact>-->

  <equality>
    <joint joint1="left_finger" joint2="right_finger" polycoef="0 -1 0 0 0"/>
  </equality>

  <actuator><!-- kp="75" kv="5" -->
    <motor forcerange="-35 35" class="wx250s" name="waist" joint="waist"   ctrlrange="-1 1" ctrllimited="true" gear="150"/>
    <motor forcerange="-35 35"  class="wx250s" name="shoulder" joint="shoulder"   ctrlrange="-1 1" ctrllimited="true" gear="150"/>
    <motor forcerange="-35 35"  class="wx250s" name="elbow" joint="elbow"  ctrlrange="-1 1" ctrllimited="true" gear="150"/>
    <motor forcerange="-35 35" class="wx250s" name="forearm_roll" joint="forearm_roll" ctrlrange="-1 1" ctrllimited="true" gear="150"/>
    <motor  forcerange="-35 35" class="wx250s" name="wrist_angle" joint="wrist_angle" ctrlrange="-1 1" ctrllimited="true" gear="150"/>
    <motor  forcerange="-1 1"  class="wx250s" name="wrist_rotate" joint="wrist_rotate"   ctrlrange="-1 1" ctrllimited="true" gear="1"/>
    <motor  forcerange="-1 1"  class="wx250s" name="gripper" joint="left_finger" ctrlrange="-1 1" ctrllimited="true" gear="1"/> <!---->
  </actuator>

  <!--
  <actuator>
    <position forcerange="-35 35" kv="5" class="wx250s" name="waist" joint="waist"   ctrlrange="-3.14158 3.14158" ctrllimited="true" gear="1"/>
    <position forcerange="-35 35" kv="5" class="wx250s" name="shoulder" joint="shoulder"   ctrlrange="-1.88496 1.98968" ctrllimited="true" gear="1"/>
    <position forcerange="-35 35" kv="10" class="wx250s" name="elbow" joint="elbow"  ctrlrange="-2.14675 1.6057" ctrllimited="true" gear="1"/>
    <position forcerange="-35 35" kv="10" class="wx250s" name="forearm_roll" joint="forearm_roll" ctrlrange="-3.14158 3.14158" ctrllimited="true" gear="1"/>
    <position  forcerange="-35 35" kv="10" class="wx250s" name="wrist_angle" joint="wrist_angle" ctrlrange="-1.74533 2.14675" ctrllimited="true" gear="1"/>
    <position  forcerange="-35 35" kv="10" class="wx250s" name="wrist_rotate" joint="wrist_rotate"   ctrlrange="-3.14158 3.14158" ctrllimited="true" gear="1"/>
    <position  forcerange="-35 35" kv="10" class="wx250s" name="gripper" joint="left_finger" ctrlrange="0.015 0.037" ctrllimited="true" gear="1"/>
  </actuator>-->
</mujoco>
